Workbook

Sheet Bảng 1 (tính điểm CC)
A1: CHI CỤC HẢI QUAN KH U VỰC XVI
A2: HẢI QUAN CỬA KHẨU QUỐC TẾ TÀ LÙNG
A4: Họ và tên:
A5: Vị trí việc làm/nhiệm vụ được phân công chuyên trách: Giám sát quản lý hải quan
A6: Đơn vị công tác: Hải quan cửa khẩu quốc tế Tà Lùng
E7: Bảng 1. Cách tính điểm số lượng, tiến độ, chất lượng
A8: STT | B8: Nội dung nhiệm vụ | C8: Giao nhiệm vụ | H8: ĐÁNH GIÁ
H9: Đánh giá số lượng | J9: Đánh giá số lượng tiến độ | M9: Đánh giá chất lượng
C10: Ngày hết hạn | D10: Sản phẩm/công việc | E10: Hệ số quy đổi | F10: Số lượng giao | G10: Số lượng giao quy đổi | H10: Số lượng hoàn thành thực tế | I10: Số lượng hoàn thành thực tế quy đổi | J10: Ngày hoàn thành | K10: Số lần chậm tiến độ | L10: Số lượng hoàn thành thực tế đạt tiến độ quy đổi | M10: Số lần yêu cầu làm lại | N10: Số lượng hoàn thành thực tế đạt chất lượng quy đổi
A11: (1) | B11: (2) | C11: (3) | D11: (4) | E11: (5) | F11: (6) | G11: (7) = (5)*(6) | H11: (8) | I11: (9) = (5)*(8) | J11: (10) | K11: (11) (10)-(3) | L11: (12) = (9)-(11)*25%*(9) | M11: (13) | N11: (14)=(9)-(13)*25%*(9)
A12: 1 | H12: =F12 -> 0 | I12: =E12*H12 -> 0 | J12: =C12 -> 0 | K12: =IF(J12-C12>0,J12-C12,0) -> 0 | L12: =I12-K12*25%*I12 -> 0 | N12: =I12-M12*25%*I12 -> 0
A13: 2 | H13: =F13 -> 0 | I13: =E13*H13 -> 0 | J13: =C13 -> 0 | K13: =IF(J13-C13>0,J13-C13,0) -> 0 | L13: =I13-K13*25%*I13 -> 0 | N13: =I13-M13*25%*I13 -> 0
A14: 3 | H14: =F14 -> 0 | I14: =E14*H14 -> 0 | J14: =C14 -> 0 | K14: =IF(J14-C14>0,J14-C14,0) -> 0 | L14: =I14-K14*25%*I14 -> 0 | N14: =I14-M14*25%*I14 -> 0
A15: 4 | H15: =F15 -> 0 | I15: =E15*H15 -> 0 | J15: =C15 -> 0 | K15: =IF(J15-C15>0,J15-C15,0) -> 0 | L15: =I15-K15*25%*I15 -> 0 | N15: =I15-M15*25%*I15 -> 0
A16: 5 | H16: =F16 -> 0 | I16: =E16*H16 -> 0 | J16: =C16 -> 0 | K16: =IF(J16-C16>0,J16-C16,0) -> 0 | L16: =I16-K16*25%*I16 -> 0 | N16: =I16-M16*25%*I16 -> 0
A17: 6 | H17: =F17 -> 0 | I17: =E17*H17 -> 0 | J17: =C17 -> 0 | K17: =IF(J17-C17>0,J17-C17,0) -> 0 | L17: =I17-K17*25%*I17 -> 0 | N17: =I17-M17*25%*I17 -> 0
A18: 7 | H18: =F18 -> 0 | I18: =E18*H18 -> 0 | J18: =C18 -> 0 | K18: =IF(J18-C18>0,J18-C18,0) -> 0 | L18: =I18-K18*25%*I18 -> 0 | N18: =I18-M18*25%*I18 -> 0
A19: 8 | H19: =F19 -> 0 | I19: =E19*H19 -> 0 | J19: =C19 -> 0 | K19: =IF(J19-C19>0,J19-C19,0) -> 0 | L19: =I19-K19*25%*I19 -> 0 | N19: =I19-M19*25%*I19 -> 0
A20: 9 | H20: =F20 -> 0 | I20: =E20*H20 -> 0 | J20: =C20 -> 0 | K20: =IF(J20-C20>0,J20-C20,0) -> 0 | L20: =I20-K20*25%*I20 -> 0 | N20: =I20-M20*25%*I20 -> 0
A21: 10 | H21: =F21 -> 0 | I21: =E21*H21 -> 0 | J21: =C21 -> 0 | K21: =IF(J21-C21>0,J21-C21,0) -> 0 | L21: =I21-K21*25%*I21 -> 0 | N21: =I21-M21*25%*I21 -> 0
A22: 11 | H22: =F22 -> 0 | I22: =E22*H22 -> 0 | J22: =C22 -> 0 | K22: =IF(J22-C22>0,J22-C22,0) -> 0 | L22: =I22-K22*25%*I22 -> 0 | N22: =I22-M22*25%*I22 -> 0
A23: 12 | H23: =F23 -> 0 | I23: =E23*H23 -> 0 | J23: =C23 -> 0 | K23: =IF(J23-C23>0,J23-C23,0) -> 0 | L23: =I23-K23*25%*I23 -> 0 | N23: =I23-M23*25%*I23 -> 0
... A71: 60 | H71: =F71 -> 0 | I71: =E71*H71 -> 0 | J71: =C71 -> 0 | K71: =IF(J71-C71>0,J71-C71,0) -> 0 | L71: =I71-K71*25%*I71 -> 0 | N71: =I71-M71*25%*I71 -> 0
A72: TỔNG CỔNG | G72: =SUM(G12:G71) -> 0 | H72: =SUM(H12:H71) -> 0 | I72: =SUM(I12:I71) -> 0 | L72: =SUM(L12:L71) -> 0 | M72: =SUM(M12:M71) -> 0 | N72: =SUM(N12:N71) -> 0
A73: Điểm (%) về số lượng [= (9)/(7)] | I73: =+I72/G72*100 -> 0 | J73: Điểm (%) về tiến độ [= (12)/(7)] | L73: =(L72/G72)*100 -> 0 | M73: Điểm % chất lượng [= (14)/(7)] | N73: =N72/G72*100 -> 0
A75: Ghi chú
A76: Cột 2,4,5 tự động lấy danh mục sản phẩm/ công việc đã được phê duyệt Tờ trình 14838/TTr-CHQ ngày 03/4/2026; Cột 3,6 sẽ do người quản lý giao; Cột 8 cá nhân tự báo cáo, người quản lý phê duyệt;
A77: II. Cách tính kết quả thực hiện nhiệm vụ của công chức Công thức: Điểm đánh giá: a + b + c 3
A78: STT | B78: Chi tiêu đánh giá | C78: Đơn vị tính | D78: Kết quả thực hiện | E78: Sau khi tính điểm thực hiện đánh giá theo công thức đối với công chức tại bảng biểu là 77%, tiếp tục thực hiện bước tiếp theo là theo dõi đánh giá công chức tháng theo công thức như sau: Tổng điểm theo dõi = Điểm tiêu chí chung + (Điểm giá x70) Ví dụ: Tổng hợp điểm theo dõi đánh giá tháng của công chức không giữ chức vụ quản lý theo ví dụ điểm 4.1 Khoản 4, Chương VI "Sổ tay hướng dẫn" '- Điểm tiêu chung: 30 điểm '- Điểm đánh giá: 77% x 70 = 53,9 '- Tổng điểm theo dõi đánh giá của tháng: 30 + 53,9 = 83,9 | I78: Điểm
A79: a | B79: Điểm tỉ lệ phần trăm (%) về số lượng kết quả thực hiện nhiệm vụ | C79: % | D79: =H73
A80: b | B80: Điểm tỷ lệ phần trăm (%) về chất lượng kết quả thực hiện nhiệm vụ | C80: % | D80: =L73 -> 81.203029
A81: c | B81: Điểm tỷ lệ phần trăm (%) về tiến độ kết quả thực hiện nhiệm vụ | C81: % | D81: =N73 -> 100
A82: Điểm đánh giá | C82: % | D82: =SUM(D79:D81)/3 -> 60.40101
A84: III. Cách tính điểm tiêu chí kết quả thực hiện nhiệm vụ của công chức giữ chức vụ lãnh đạo quản lý Công thức: Điểm đánh giá: Điểm đánh giá: a + b + c + d + đ + e 6
A85: STT | B85: Chi tiêu đánh giá | C85: Đơn vị tính | D85: Kết quả thực hiện
A86: a | B86: Điểm tỉ lệ phần trăm (%) về số lượng kết quả thực hiện nhiệm vụ | C86: %
A87: b | B87: Điểm tỷ lệ phần trăm (%) về chất lượng kết quả thực hiện nhiệm vụ | C87: %
A88: c | B88: Điểm tỷ lệ phần trăm (%) về tiến độ kết quả thực hiện nhiệm vụ | C88: %
A89: d | B89: Điểm tỷ lệ phần trăm (%) về kết quả hoạt động của lĩnh vực được giao lãnh đạo, quản lý, phụ trách | C89: %
A90: đ | B90: Điểm tỷ lệ phần trăm (%) về khả năng tổ chức triển khai thực hiện nhiệm vụ | C90: %
...

Sheet Biểu 01A (CC)
C1: Mẫu 01A
A2: CHI CỤC HẢI QUAN KHU VỰC XVI CỘNG HÒA XÃ HỘI CHỦ NGHĨA VIỆT NAM
A3: HẢI QUAN CKQT TÀ LÙNG Độc lập - Tự do - Hạnh phúc
A5: PHIẾU THEO DÕI, ĐÁNH GIÁ CÔNG CHỨC
A6: (Dành cho công chức không giữ chức vụ lãnh đạo)
A7: Tháng 9/2026
B8: ='Bảng 1 (tính điểm CC)'!A4 -> Họ và tên: Nguyễn Hải Yên
B9: ='Bảng 1 (tính điểm CC)'!A5 -> Vị trí việc làm/nhiệm vụ được phân công chuyên trách: Giám sát quản lý hải quan
B10: Đơn vị công tác: Hải quan cửa khẩu quốc tế Tà Lùng.
B12: I. KẾT QUẢ THEO DÕI, ĐÁNH GIÁ THEO TIÊU CHÍ CHUNG:
A13: TT | B13: Tiêu chí chấm điểm | C13: Điểm tối đa | D13: Điểm do cá nhân tự chấm
A14: (1) | B14: (2) | C14: (3) | D14: (4)
A15: I | B15: Phẩm chất chính trị, phẩm chất đạo đức, văn hóa thực thi công vụ và ý thức kỷ luật, kỷ cương trong thực thi công vụ | D15: =D16+D17 -> 10
B16: Phẩm chất chính trị, phẩm chất đạo đức, văn hóa thực thi công vụ
B17: Ý thức kỷ luật, kỷ cương trong thực thi công vụ
A18: II | B18: Năng lực chuyên môn, nghiệp vụ theo yêu cầu của vị trí việc làm; khả năng đáp ứng yêu cầu thực thi nhiệm vụ được giao; tinh thần trách nhiệm trong thực thi công vụ; thái độ phục vụ người dân, doanh nghiệp và khả năng phối hợp với đồng nghiệp | D18: =D19+D20+D21+D22 -> 10
B19: Năng lực chuyên môn, nghiệp vụ theo yêu cầu của vị trí việc làm
B20: Khả năng đáp ứng yêu cầu thực thi nhiệm vụ được giao thường xuyên, đột xuất
B21: Tinh thần trách nhiệm trong thực thi công vụ
B22: Thái độ phục vụ người dân, doanh nghiệp và khả năng phối hợp với đồng nghiệp
A23: III | B23: Năng lực đổi mới, sáng tạo, dám nghĩ, dám làm, dám chịu trách nhiệm vì lợi ích chung trong thực thi công vụ | D23: =D24+D25+D26+D27 -> 8.5
B24: Có sản phẩm, giải pháp đột phá, sáng tạo đem lại giá trị, hiệu quả thiết thực, tác động tích cực đến kết quả thực hiện nhiệm vụ của cơ quan, tổ chức, đơn vị.
B25: Sẵn sàng tham gia thực hiện nhiệm vụ chính trị đặc biệt quan trọng, nhiệm vụ có tính chất đột xuất, phức tạp hoặc trong điều kiện khó khăn.
B26: Có tinh thần chịu trách nhiệm trước kết quả công việc; chủ động nhận trách nhiệm khi có sai sót và có biện pháp khắc phục rõ ràng, cụ thể.
B27: Chủ động đưa ra quyết định trong phạm vi thẩm quyền, không né tránh; có tinh thần tiên phong trong thực hiện những nhiệm vụ mới.
A28: Tổng cộng | D28: =D23+D18+D15 -> 28.5
B30: II. TỔNG HỢP KẾT QUẢ TỰ ĐÁNH GIÁ, XẾP LOẠI:
B31: 1. Điểm tiêu chí chung (tối đa 30 điểm): | C31: =D28 -> 28.5
B32: (Kết quả chấm điểm tại mục I)
B33: 2. Điểm tiêu chí kết quả thực hiện nhiệm vụ: (tối đa 70 điểm): | D33: =D38 -> 65.61404
B34: a. Điểm tỷ lệ % đánh giá về số lượng (a): | D34: =+'Bảng 1 (tính điểm CC)'!I73 -> 100
B35: b. Điểm tỷ lệ % đánh giá về tiến độ (b): | D35: ='Bảng 1 (tính điểm CC)'!L73 -> 81.203029
B36: c. Điểm tỷ lệ % đánh giá về chất lượng (c): | D36: =+'Bảng 1 (tính điểm CC)'!N73 -> 100
B37: d. Điểm tỷ lệ % kết quả thực hiện nhiệm vụ (d = (a + b + c)/3)): | D37: =(D34+D35+D36)/3 -> 93.734343
B38: Điểm tiêu chí kết quả thực hiện nhiệm vụ (=(d*70)/100)): | D38: =D37*70/100 -> 65.61404
B39: 3. Tổng điểm theo dõi, đánh giá (3=1+2): | D39: =D33+C31 -> 94.11404
B40: 4. Ưu điểm: ................................................................................................................
A41: …............................................................................................................................................................................
A42: …............................................................................................................................................................................
B43: 5. Hạn chế, khuyết điểm: ..........................................................................................
...
